<?xml version="1.0" encoding="utf-8"?>
<!-- This URDF was automatically created by SolidWorks to URDF Exporter! Originally created by Stephen Brawner (brawner@gmail.com) 
     Commit Version: 1.5.1-0-g916b5db  Build Version: 1.5.7152.31018
     For more information, please see http://wiki.ros.org/sw_urdf_exporter -->
<robot
  name="4wheel_ball">
  <link
    name="base_link">
    <inertial>
      <origin
        xyz="0.00088514 0.09157 -0.015791"
        rpy="0 0 0" />
      <mass
        value="5.3249" />
      <inertia
        ixx="0.021938"
        ixy="-4.0175E-06"
        ixz="-1.4798E-06"
        iyy="0.023203"
        iyz="-8.0652E-06"
        izz="0.014905" />
    </inertial>
    <visual>
      <origin
        xyz="0 0 0"
        rpy="0 0 0" />
      <geometry>
        <mesh
          filename="package://4wheel_ball/meshes/base_link.STL" />
      </geometry>
      <material
        name="">
        <color
          rgba="0.75294 0.75294 0.75294 1" />
      </material>
    </visual>
    <collision>
      <origin
        xyz="0 0 0"
        rpy="0 0 0" />
      <geometry>
        <mesh
          filename="package://4wheel_ball/meshes/base_link.STL" />
      </geometry>
    </collision>
  </link>
  <link
    name="right_front_suspension">
    <inertial>
      <origin
        xyz="0.072447 -0.0024231 -0.066755"
        rpy="0 0 0" />
      <mass
        value="0.26437" />
      <inertia
        ixx="3.2075E-05"
        ixy="1.4412E-07"
        ixz="6.3085E-08"
        iyy="6.227E-05"
        iyz="-2.0189E-07"
        izz="6.2852E-05" />
    </inertial>
    <visual>
      <origin
        xyz="0 0 0"
        rpy="0 0 0" />
      <geometry>
        <mesh
          filename="package://4wheel_ball/meshes/right_front_suspension.STL" />
      </geometry>
      <material
        name="">
        <color
          rgba="0.75294 0.75294 0.75294 1" />
      </material>
    </visual>
    <collision>
      <origin
        xyz="0 0 0"
        rpy="0 0 0" />
      <geometry>
        <mesh
          filename="package://4wheel_ball/meshes/right_front_suspension.STL" />
      </geometry>
    </collision>
  </link>
  <joint
    name="right_front_suspension"
    type="fixed">
    <origin
      xyz="-0.21292 -0.11437 -0.037202"
      rpy="2.834 0 0" />
    <parent
      link="base_link" />
    <child
      link="right_front_suspension" />
    <axis
      xyz="0 0 0" />
    <limit
      lower="0"
      upper="0"
      effort="0"
      velocity="0" />
  </joint>
  <link
    name="right_front_wheel">
    <inertial>
      <origin
        xyz="0.014171 0 -1.3878E-17"
        rpy="0 0 0" />
      <mass
        value="0.23877" />
      <inertia
        ixx="0.00029907"
        ixy="-3.9522E-37"
        ixz="6.92E-37"
        iyy="0.00016737"
        iyz="-8.4703E-22"
        izz="0.00016737" />
    </inertial>
    <visual>
      <origin
        xyz="0 0 0"
        rpy="0 0 0" />
      <geometry>
        <mesh
          filename="package://4wheel_ball/meshes/right_front_wheel.STL" />
      </geometry>
      <material
        name="">
        <color
          rgba="1 1 1 1" />
      </material>
    </visual>
    <collision>
      <origin
        xyz="0 0 0"
        rpy="0 0 0" />
      <geometry>
        <mesh
          filename="package://4wheel_ball/meshes/right_front_wheel.STL" />
      </geometry>
    </collision>
  </link>
  <joint
    name="right_front_wheel"
    type="continuous">
    <origin
      xyz="0 0.00097405 -0.03369"
      rpy="-1.3077 0 0" />
    <parent
      link="right_front_suspension" />
    <child
      link="right_front_wheel" />
    <axis
      xyz="1 0 0" />
    <limit
      effort="3.1"
      velocity="7" />
  </joint>
  <link
    name="left_front_suspension">
    <inertial>
      <origin
        xyz="0.066688 0.0036428 -0.064837"
        rpy="0 0 0" />
      <mass
        value="0.26437" />
      <inertia
        ixx="3.2075E-05"
        ixy="-1.4412E-07"
        ixz="-6.3085E-08"
        iyy="6.227E-05"
        iyz="-2.0189E-07"
        izz="6.2852E-05" />
    </inertial>
    <visual>
      <origin
        xyz="0 0 0"
        rpy="0 0 0" />
      <geometry>
        <mesh
          filename="package://4wheel_ball/meshes/left_front_suspension.STL" />
      </geometry>
      <material
        name="">
        <color
          rgba="0.75294 0.75294 0.75294 1" />
      </material>
    </visual>
    <collision>
      <origin
        xyz="0 0 0"
        rpy="0 0 0" />
      <geometry>
        <mesh
          filename="package://4wheel_ball/meshes/left_front_suspension.STL" />
      </geometry>
    </collision>
  </link>
  <joint
    name="left_front_suspension"
    type="fixed">
    <origin
      xyz="0.20716 -0.075688 -0.037202"
      rpy="2.834 0 3.1416" />
    <parent
      link="base_link" />
    <child
      link="left_front_suspension" />
    <axis
      xyz="0 0 0" />
    <limit
      lower="0"
      upper="0"
      effort="0"
      velocity="0" />
  </joint>
  <link
    name="left_front_wheel">
    <inertial>
      <origin
        xyz="-0.008411 -1.3878E-17 0"
        rpy="0 0 0" />
      <mass
        value="0.23877" />
      <inertia
        ixx="0.00029907"
        ixy="3.5444E-22"
        ixz="-1.8433E-21"
        iyy="0.00016737"
        iyz="6.7763E-21"
        izz="0.00016737" />
    </inertial>
    <visual>
      <origin
        xyz="0 0 0"
        rpy="0 0 0" />
      <geometry>
        <mesh
          filename="package://4wheel_ball/meshes/left_front_wheel.STL" />
      </geometry>
      <material
        name="">
        <color
          rgba="1 1 1 1" />
      </material>
    </visual>
    <collision>
      <origin
        xyz="0 0 0"
        rpy="0 0 0" />
      <geometry>
        <mesh
          filename="package://4wheel_ball/meshes/left_front_wheel.STL" />
      </geometry>
    </collision>
  </link>
  <joint
    name="left_front_wheel"
    type="continuous">
    <origin
      xyz="0 -0.018219 -0.039786"
      rpy="-0.026787 0 3.1416" />
    <parent
      link="left_front_suspension" />
    <child
      link="left_front_wheel" />
    <axis
      xyz="1 0 0" />
    <limit
      effort="3.1"
      velocity="7" />
  </joint>
  <link
    name="right_back_suspension">
    <inertial>
      <origin
        xyz="-0.0067868 0.01067 0.059195"
        rpy="0 0 0" />
      <mass
        value="0.11411" />
      <inertia
        ixx="7.8941E-05"
        ixy="5.5541E-22"
        ixz="1.1472E-06"
        iyy="5.1512E-05"
        iyz="5.8796E-21"
        izz="7.839E-05" />
    </inertial>
    <visual>
      <origin
        xyz="0 0 0"
        rpy="0 0 0" />
      <geometry>
        <mesh
          filename="package://4wheel_ball/meshes/right_back_suspension.STL" />
      </geometry>
      <material
        name="">
        <color
          rgba="0.75294 0.75294 0.75294 1" />
      </material>
    </visual>
    <collision>
      <origin
        xyz="0 0 0"
        rpy="0 0 0" />
      <geometry>
        <mesh
          filename="package://4wheel_ball/meshes/right_back_suspension.STL" />
      </geometry>
    </collision>
  </link>
  <joint
    name="right_back_suspension"
    type="fixed">
    <origin
      xyz="-0.23339 0.12116 0"
      rpy="-1.5708 0 -2.2503" />
    <parent
      link="base_link" />
    <child
      link="right_back_suspension" />
    <axis
      xyz="0 0 0" />
    <limit
      lower="0"
      upper="0"
      effort="0"
      velocity="0" />
  </joint>
  <link
    name="left_back_suspension">
    <inertial>
      <origin
        xyz="-0.0067868 0.01067 0.059195"
        rpy="0 0 0" />
      <mass
        value="0.11411" />
      <inertia
        ixx="7.8941E-05"
        ixy="1.7655E-21"
        ixz="1.1472E-06"
        iyy="5.1512E-05"
        iyz="3.4904E-21"
        izz="7.839E-05" />
    </inertial>
    <visual>
      <origin
        xyz="0 0 0"
        rpy="0 0 0" />
      <geometry>
        <mesh
          filename="package://4wheel_ball/meshes/left_back_suspension.STL" />
      </geometry>
      <material
        name="">
        <color
          rgba="0.75294 0.75294 0.75294 1" />
      </material>
    </visual>
    <collision>
      <origin
        xyz="0 0 0"
        rpy="0 0 0" />
      <geometry>
        <mesh
          filename="package://4wheel_ball/meshes/left_back_suspension.STL" />
      </geometry>
    </collision>
  </link>
  <joint
    name="left_back_suspension"
    type="fixed">
    <origin
      xyz="0.23339 0.055845 0"
      rpy="-1.5708 0 0.89134" />
    <parent
      link="base_link" />
    <child
      link="left_back_suspension" />
    <axis
      xyz="0 0 0" />
    <limit
      lower="0"
      upper="0"
      effort="0"
      velocity="0" />
  </joint>
  <link
    name="cam1">
    <inertial>
      <origin
        xyz="0.049836 0.061784 0.068723"
        rpy="0 0 0" />
      <mass
        value="0.043612" />
      <inertia
        ixx="4.2948E-06"
        ixy="-8.8548E-10"
        ixz="-1.0183E-09"
        iyy="2.2106E-05"
        iyz="2.1758E-08"
        izz="2.3571E-05" />
    </inertial>
    <visual>
      <origin
        xyz="0 0 0"
        rpy="0 0 0" />
      <geometry>
        <mesh
          filename="package://4wheel_ball/meshes/cam1.STL" />
      </geometry>
      <material
        name="">
        <color
          rgba="0.79216 0.81961 0.93333 1" />
      </material>
    </visual>
    <collision>
      <origin
        xyz="0 0 0"
        rpy="0 0 0" />
      <geometry>
        <mesh
          filename="package://4wheel_ball/meshes/cam1.STL" />
      </geometry>
    </collision>
  </link>
  <joint
    name="cam1"
    type="fixed">
    <origin
      xyz="-0.049835 -0.022219 0.13322"
      rpy="2.3562 0 0" />
    <parent
      link="base_link" />
    <child
      link="cam1" />
    <axis
      xyz="0 0 0" />
  </joint>
  <link
    name="cam2">
    <inertial>
      <origin
        xyz="0.049836 0.061784 0.068723"
        rpy="0 0 0" />
      <mass
        value="0.043612" />
      <inertia
        ixx="4.2948E-06"
        ixy="-8.8579E-10"
        ixz="-1.0181E-09"
        iyy="2.2106E-05"
        iyz="2.1758E-08"
        izz="2.3571E-05" />
    </inertial>
    <visual>
      <origin
        xyz="0 0 0"
        rpy="0 0 0" />
      <geometry>
        <mesh
          filename="package://4wheel_ball/meshes/cam2.STL" />
      </geometry>
      <material
        name="">
        <color
          rgba="0.79216 0.81961 0.93333 1" />
      </material>
    </visual>
    <collision>
      <origin
        xyz="0 0 0"
        rpy="0 0 0" />
      <geometry>
        <mesh
          filename="package://4wheel_ball/meshes/cam2.STL" />
      </geometry>
    </collision>
  </link>
  <joint
    name="cam2"
    type="fixed">
    <origin
      xyz="-0.049839 -0.046422 0.10251"
      rpy="1.5708 0 0" />
    <parent
      link="base_link" />
    <child
      link="cam2" />
    <axis
      xyz="0 0 0" />
    <limit
      lower="0"
      upper="0"
      effort="0"
      velocity="0" />
  </joint>
  <link
    name="lidar">
    <inertial>
      <origin
        xyz="0 0 0"
        rpy="0 0 0" />
      <mass
        value="0" />
      <inertia
        ixx="0"
        ixy="0"
        ixz="0"
        iyy="0"
        iyz="0"
        izz="0" />
    </inertial>
    <visual>
      <origin
        xyz="0 0 0"
        rpy="0 0 0" />
      <geometry>
        <mesh
          filename="package://4wheel_ball/meshes/lidar.STL" />
      </geometry>
      <material
        name="">
        <color
          rgba="1 1 1 1" />
      </material>
    </visual>
    <collision>
      <origin
        xyz="0 0 0"
        rpy="0 0 0" />
      <geometry>
        <mesh
          filename="package://4wheel_ball/meshes/lidar.STL" />
      </geometry>
    </collision>
  </link>
  <joint
    name="lidar"
    type="fixed">
    <origin
      xyz="0.13292 -0.027939 -0.53869"
      rpy="-1.5708 0 -1.5708" />
    <parent
      link="base_link" />
    <child
      link="lidar" />
    <axis
      xyz="0 0 0" />
    <limit
      lower="0"
      upper="0"
      effort="0"
      velocity="0" />
  </joint>
</robot>